<?xml version ="1.0"?>
<robot name="my_robot">
    <link name="base_link">
        <visual>
            <geometry>
                <box size="1 0.5 0.25"/>
            </geometry>
        </visual>
    </link>
    <link name="left_wheel">
        <visual>
            <origin xyz = "0 0.12 0"  rpy = "1.5708 0.0 0.0"/>
            <geometry>
                <cylinder length ="0.2" radius= "0.2"/>
            </geometry>
        </visual>
    </link>
    <joint name ="left_wheel_joint" type= "continuous">
        <origin xyz = "0.40 0.25 0"/>
        <parent link ="base_link"/>
        <child link = "left_wheel"/>
        <axis xyz = "0.0 1.0 0.0"/>
    </joint>
        
</robot>