<?xml version="1.0" encoding="utf-8"?>
<!-- =================================================================================== -->
<!-- |    This document was autogenerated by xacro from 02-description.xacro           | -->
<!-- |    EDITING THIS FILE BY HAND IS NOT RECOMMENDED                                 | -->
<!-- =================================================================================== -->
<robot name="my_robot">
  <!--SECTION PRINCIPALE-->
  <link name="base_link">
    <visual>
      <geometry>
        <box size="1.0 0.55 0.25"/>
      </geometry>
    </visual>
    <collision>
      <geometry>
        <box size="1.0 0.55 0.25"/>
      </geometry>
    </collision>
  </link>
  <!--intertial link indispensable car base_link ne peut pas porter de masse et d'inertie-->
  <link name="inertial_link">
    <inertial>
      <mass value="10"/>
      <inertia ixx="1.21666666667" ixy="1.375" ixz="0.625" iyy="3.54166666667" iyz="0.34375" izz="4.34166666667"/>
    </inertial>
  </link>
  <joint name="inertial_joint" type="fixed">
    <parent link="base_link"/>
    <child link="inertial_link"/>
  </joint>
  <link name="fl_wheel">
    <visual>
      <origin rpy="1.57079632679 0.0 0.0" xyz=" 0.0 0.075 0.0"/>
      <geometry>
        <cylinder length="0.15" radius="0.15"/>
      </geometry>
    </visual>
    <inertial>
      <mass value="1"/>
      <inertia ixx="0.0075" ixy="0.0" ixz="0.0" iyy="0.0075" iyz="0.0" izz="0.01125"/>
    </inertial>
    <collision>
      <origin rpy="1.57079632679 0.0 0.0" xyz=" 0.0 0.075 0.0"/>
      <geometry>
        <cylinder length="0.15" radius="0.15"/>
      </geometry>
    </collision>
  </link>
  <joint name="fl_wheel_joint" type="continuous">
    <origin xyz="0.4 0.275 0.0"/>
    <parent link="base_link"/>
    <child link="fl_wheel"/>
    <axis xyz="0.0 1.0 0.0"/>
  </joint>
  <link name="fr_wheel">
    <visual>
      <origin rpy="1.57079632679 0.0 0.0" xyz=" 0.0 -0.075 0.0"/>
      <geometry>
        <cylinder length="0.15" radius="0.15"/>
      </geometry>
    </visual>
    <inertial>
      <mass value="1"/>
      <inertia ixx="0.0075" ixy="0.0" ixz="0.0" iyy="0.0075" iyz="0.0" izz="0.01125"/>
    </inertial>
    <collision>
      <origin rpy="1.57079632679 0.0 0.0" xyz=" 0.0 -0.075 0.0"/>
      <geometry>
        <cylinder length="0.15" radius="0.15"/>
      </geometry>
    </collision>
  </link>
  <joint name="fr_wheel_joint" type="continuous">
    <origin xyz="0.4 -0.275 0.0"/>
    <parent link="base_link"/>
    <child link="fr_wheel"/>
    <axis xyz="0.0 1.0 0.0"/>
  </joint>
  <link name="rl_wheel">
    <visual>
      <origin rpy="1.57079632679 0.0 0.0" xyz=" 0.0 0.075 0.0"/>
      <geometry>
        <cylinder length="0.15" radius="0.15"/>
      </geometry>
    </visual>
    <inertial>
      <mass value="1"/>
      <inertia ixx="0.0075" ixy="0.0" ixz="0.0" iyy="0.0075" iyz="0.0" izz="0.01125"/>
    </inertial>
    <collision>
      <origin rpy="1.57079632679 0.0 0.0" xyz=" 0.0 0.075 0.0"/>
      <geometry>
        <cylinder length="0.15" radius="0.15"/>
      </geometry>
    </collision>
  </link>
  <joint name="rl_wheel_joint" type="continuous">
    <origin xyz="-0.4 0.275 0.0"/>
    <parent link="base_link"/>
    <child link="rl_wheel"/>
    <axis xyz="0.0 1.0 0.0"/>
  </joint>
  <link name="rr_wheel">
    <visual>
      <origin rpy="1.57079632679 0.0 0.0" xyz=" 0.0 -0.075 0.0"/>
      <geometry>
        <cylinder length="0.15" radius="0.15"/>
      </geometry>
    </visual>
    <inertial>
      <mass value="1"/>
      <inertia ixx="0.0075" ixy="0.0" ixz="0.0" iyy="0.0075" iyz="0.0" izz="0.01125"/>
    </inertial>
    <collision>
      <origin rpy="1.57079632679 0.0 0.0" xyz=" 0.0 -0.075 0.0"/>
      <geometry>
        <cylinder length="0.15" radius="0.15"/>
      </geometry>
    </collision>
  </link>
  <joint name="rr_wheel_joint" type="continuous">
    <origin xyz="-0.4 -0.275 0.0"/>
    <parent link="base_link"/>
    <child link="rr_wheel"/>
    <axis xyz="0.0 1.0 0.0"/>
  </joint>
</robot>

